Workbook
Name rate: 'דוח החזר'!$K$4:$L$9
Name RATELI: 'דוח החזר'!$G$4:$H$10

Sheet דוח נסיעה לחו"ל 
A1: דו"ח נסיעה לחו"ל
A3: שם החברה/העסק:
A4: שם הנוסע:
A5: תפקיד:
A6: מטרת הנסיעה:
C8: ימי שהייה עסקיים
B9: יעדי הנסיעה | C9: מ תאריך - | D9: עד תאריך | E9: סה"כ ימים
A10: 1 | C10: ='דוח החזר'!E12 | D10: ='דוח החזר'!F12 | E10: ='דוח החזר'!G12
A11: 2 | E11: ='דוח החזר'!G13
A12: 3 | E12: ='דוח החזר'!G14
A14: סה"כ ימי שהייה בחו"ל: | B14: =SUM(E10:E12) -> 0
B17: הוצאות עבור: | C17: סכום ההוצאה בשקלים | D17: סכום ההוצאה במט"ח
B18: טיסות | C18: =SUMIFS('Jonathan Zvi Shmuely – China – 2026-03-23'!G:G,'Jonathan Zvi Shmuely – China – 2026-03-23'!B:B,B18) -> #N/A | D18: =C18/VLOOKUP("USD",RATELI,2,0) -> #N/A
B19: נסיעות בתחבורה ציבורית | C19: =SUMIFS('Jonathan Zvi Shmuely – China – 2026-03-23'!G:G,'Jonathan Zvi Shmuely – China – 2026-03-23'!B:B,B19) -> #N/A | D19: =C19/VLOOKUP("USD",RATELI,2,0) -> #N/A
B20: לינה ללא ארוחות | C20: =SUMIFS('Jonathan Zvi Shmuely – China – 2026-03-23'!G:G,'Jonathan Zvi Shmuely – China – 2026-03-23'!B:B,B20) -> #N/A | D20: =C20/VLOOKUP("USD",RATELI,2,0) -> #N/A
B21: השכרת רכב | C21: =SUMIFS('Jonathan Zvi Shmuely – China – 2026-03-23'!G:G,'Jonathan Zvi Shmuely – China – 2026-03-23'!B:B,B21) -> #N/A | D21: =C21/VLOOKUP("USD",RATELI,2,0) -> #N/A
B22: אירוח אורחים בחול | C22: =SUMIFS('Jonathan Zvi Shmuely – China – 2026-03-23'!G:G,'Jonathan Zvi Shmuely – China – 2026-03-23'!B:B,B22) -> #N/A | D22: =C22/VLOOKUP("USD",RATELI,2,0) -> #N/A
B23: תקשורת | C23: =SUMIFS('Jonathan Zvi Shmuely – China – 2026-03-23'!G:G,'Jonathan Zvi Shmuely – China – 2026-03-23'!B:B,B23) -> #N/A | D23: =C23/VLOOKUP("USD",RATELI,2,0) -> #N/A
B24: ארוחות | C24: =SUMIFS('Jonathan Zvi Shmuely – China – 2026-03-23'!G:G,'Jonathan Zvi Shmuely – China – 2026-03-23'!B:B,B24) -> #N/A | D24: =C24/VLOOKUP("USD",RATELI,2,0) -> #N/A
B25: הוצאות שונות | C25: =SUMIFS('Jonathan Zvi Shmuely – China – 2026-03-23'!G:G,'Jonathan Zvi Shmuely – China – 2026-03-23'!B:B,B25) -> #N/A | D25: =C25/VLOOKUP("USD",RATELI,2,0) -> #N/A
B26: ללא קבלות | C26: =SUMIFS('Jonathan Zvi Shmuely – China – 2026-03-23'!G:G,'Jonathan Zvi Shmuely – China – 2026-03-23'!B:B,B26) -> #N/A | D26: =C26/VLOOKUP("USD",RATELI,2,0) -> #N/A
B27: סה"כ הוצאות | C27: =SUM(C18:C26) -> #N/A | D27: =SUM(D18:D26) -> #N/A

Sheet דוח החזר
C1: דו"ח החזר הוצאות
D3: שנת הדו"ח: | G3: מטבע | H3: שער המרה | J3: טבלה ממויינת תמידית לVLOOKUP
D4: 2026 | G4: ILS | H4: 1 | J4: 1 | K4: =CONCATENATE(J4,G4) -> 1ILS | L4: =+H4 -> 1
G5: RMB | H5: 0.45 | J5: 2 | K5: =CONCATENATE(J5,G5) -> 2RMB | L5: =+H5 -> 0.45
G6: HKD | H6: 0.477
C7: שם + משפחה | G7: USD | H7: 3.44 | J7: 3 | K7: =CONCATENATE(J7,G7) -> 3USD | L7: =+H7 -> 3.44
G8: THB | H8: 0.092
C9: תפקיד | G9: CNY | H9: 0.45 | J9: 5 | K9: =CONCATENATE(J9,G9) -> 5CNY | L9: =+H9 -> 0.45
C11: מדינה | D11: מטרת הנסיעה | E11: מיום | F11: עד יום | G11: ימי שהייה עסקיים | H11: הערות
C15: פרוט הוצאות
C17: טיסות
C18: תאריך | D18: יעדים | E18: סוג מטבע | F18: סכום | G18: בש"ח | H18: שולם ע"י (**) | I18: אסמכתא
B19: טיסות | G19: =IF(E19="","",IF(F19="","",(VLOOKUP(E19,RATELI,2,0)*F19))) | H19: כ. אשראי חברה
B20: טיסות | G20: =IF(E20="","",IF(F20="","",(VLOOKUP(E20,RATELI,2,0)*F20)))
B21: טיסות | G21: =IF(E21="","",IF(F21="","",(VLOOKUP(E21,RATELI,2,0)*F21)))
F22: סה"כ בש"ח | G22: =SUM(G19:G21) -> 0
E23: שולם על ידי | F23: העובד | G23: =SUMIF(H19:H21,"העובד",G19:G21) -> 0
E24: שולם ב | F24: כ. אשראי חברה | G24: =SUMIF(H19:H21,"כ. אשראי חברה",G19:G21) -> 0
C26: נסיעות בתחבורה ציבורית
C27: תאריך | D27: סוג ההוצאה (מונית/רכבת/אוטובוס/השכרת רכב/דלק/חניה) | E27: סוג מטבע | F27: סכום | G27: בש"ח | H27: שולם ע"י (**) | I27: אסמכתא
B28: נסיעות בתחבורה ציבורית
B29: נסיעות בתחבורה ציבורית
B30: נסיעות בתחבורה ציבורית
B31: נסיעות בתחבורה ציבורית
B32: נסיעות בתחבורה ציבורית
B33: נסיעות בתחבורה ציבורית
B34: נסיעות בתחבורה ציבורית
B35: נסיעות בתחבורה ציבורית
B36: נסיעות בתחבורה ציבורית
B37: נסיעות בתחבורה ציבורית
B38: נסיעות בתחבורה ציבורית
B39: נסיעות בתחבורה ציבורית
... B79: נסיעות בתחבורה ציבורית
F80: סה"כ בש"ח | G80: =SUM(G28:G79) -> 0
E81: שולם על ידי | F81: העובד | G81: =SUMIF(H28:H79,"העובד",G28:G79) -> 0
E82: שולם ב | F82: כ. אשראי חברה | G82: =SUMIF(H28:H79,"כ. אשראי חברה",G28:G79) -> 0
C84: לינה ללא ארוחות
C85: תאריך | D85: יעדים | E85: סוג מטבע | F85: סכום | G85: בש"ח | H85: שולם ע"י (**) | I85: אסמכתא
B86: לינה ללא ארוחות | G86: =IF(E86="","",IF(F86="","",(VLOOKUP(E86,RATELI,2,0)*F86))) | H86: כ. אשראי חברה
B87: לינה ללא ארוחות | G87: =IF(E87="","",IF(F87="","",(VLOOKUP(E87,RATELI,2,0)*F87)))
...

Sheet RAW
A1: date | B1: category | C1: amount | D1: currency | E1: description | F1: payment_method | G1: city | H1: country | I1: filename | J1: drive_url | K1: raw_text | L1: אסמכתא
A2: 46105 | B2: ארוחות | C2: 434 | D2: THB | E2: Suvarnabhumi McThai (McDonald's) | F2: העובד | J2: https://drive.google.com/file/d/1adgbLjfOdnyEzlwc2hTAArNNei2L3ZIH/view?usp=drivesdk | L2: =HYPERLINK("https://drive.google.com/file/d/1adgbLjfOdnyEzlwc2hTAArNNei2L3ZIH/view?usp=drivesdk","קבלה") -> קבלה
A3: 45379 | B3: נסיעות בתחבורה ציבורית | C3: 48 | D3: CNY | E3: China Ride Hail | F3: העובד | J3: https://drive.google.com/file/d/1p9D-Ts-Rq4oIypvl8MPNM5bdBIYWiAj-/view?usp=drivesdk | L3: =HYPERLINK("https://drive.google.com/file/d/1p9D-Ts-Rq4oIypvl8MPNM5bdBIYWiAj-/view?usp=drivesdk","קבלה") -> קבלה
A4: 46108 | B4: ארוחות | C4: 15.9 | D4: CNY | E4: China Jiajia Department Store | F4: העובד | J4: https://drive.google.com/file/d/1sVHrneZaeaoV4BVhTd2XtP0xGD_NFBZi/view?usp=drivesdk | L4: =HYPERLINK("https://drive.google.com/file/d/1sVHrneZaeaoV4BVhTd2XtP0xGD_NFBZi/view?usp=drivesdk","קבלה") -> קבלה
A5: 46132 | B5: ארוחות | C5: 680.9 | D5: THB | E5: Bangkok KOH HOP BAR ZONE F | F5: העובד | J5: https://drive.google.com/file/d/1jHLu4JBhozeGPpIBob6GbR06Fu13P0Te/view?usp=drivesdk | L5: =HYPERLINK("https://drive.google.com/file/d/1jHLu4JBhozeGPpIBob6GbR06Fu13P0Te/view?usp=drivesdk","קבלה") -> קבלה
A6: 45408 | B6: טיסות | C6: 339 | D6: USD | E6: Guangzhou China Southern Airlines | F6: העובד | J6: https://drive.google.com/file/d/1rCEMZOXZPqkBNyrctDHArxYFLnHHWJW7/view?usp=drivesdk | L6: =HYPERLINK("https://drive.google.com/file/d/1rCEMZOXZPqkBNyrctDHArxYFLnHHWJW7/view?usp=drivesdk","קבלה") -> קבלה

Sheet droplist
A1: New categories
A2: טיסות
A3: נסיעות בתחבורה ציבורית
A4: לינה ללא ארוחות
A5: השכרת רכב
A6: אירוח אורחים בחול
A7: תקשורת
A8: ארוחות
A9: הוצאות שונות
A10: ללא קבלות
